Workbook

Sheet README
A1: EnergyWave, Inc. — Next-Raise Budget, Forecast & Due-Diligence Workbook · v1 · 2026-09-07
A2: Prepared for Ian McLean (Founder & CEO) and the interim finance team (E57 Partners or equivalent). Driver-based, 36-month, scenario-switched.
A4: WHAT THIS IS
A5: A monthly cash-need plan for EnergyWave, Inc. only. It computes the raise size from the plan (headcount + lab + equipment + G&A + reserve) and tranches it by the three research gates, so the packet shows dollars tied to milestones rather than an open-ended ask.
A6: It contains NO device performance claims and NO technical specifications. Nothing in this file is a statement about what any configuration under test does.
A8: CONVENTIONS
A9: Blue text = input you can change. Black = formula (do not overwrite). Green = link to another sheet. Yellow fill = key lever / headline output.
A10: Every dollar input carries an 'Input status': 'From Ian' = number Ian gave; 'Placeholder' = my estimate to be validated by finance; 'Formula' = computed. Treat every Placeholder as unvalidated.
A11: Scenario lever: Assumptions!B4 (1 = Lean, 2 = Base, 3 = Full). It changes start months and equipment tiers everywhere; nothing else needs touching.
A13: SHEETS
A14: Assumptions — global drivers (scenario, start date, payroll load, reserve %, gate months, rent, recruiting fee, outsourced-finance fees).
A15: Headcount — every role with base, load flag, relocation, equity note, start month by scenario, monthly cost, 36-month total.
... A35: 6. Intercompany line stays $0 until Novak confirms the arms-length structure for both nonprofits.

Sheet Assumptions
A1: Assumptions — global drivers
A2: Blue = input. Yellow = scenario lever / headline. Status column says where each number came from.
A3: Driver | B3: Value | C3: Unit / notes | D3: Input status
A4: Scenario (1 = Lean, 2 = Base, 3 = Full) | B4: 2 | C4: Drives start months and equipment tiers everywhere | D4: Lever
A5: Model start (month 1) | B5: 46388 | C5: First month of spend after close — change freely | D5: Placeholder
A6: Horizon (months) — fixed by layout | B6: 36 | C6: Monthly sheet has 36 columns; do not change | D6: Fixed
A7: Payroll load (benefits + employer taxes) | B7: 0.22 | C7: Applied to W-2 base only | D7: Placeholder
A8: Default relocation per relocating hire | B8: 25000 | C8: Applied to the five applied-physicist hires; override per row on Headcount | D8: Placeholder
A9: Option pool (% fully diluted) — non-cash | B9: 0.12 | C9: Cap-table item, not a cash line; recorded for the packet | D9: Placeholder
A10: Reserve / contingency (% of plan spend) | B10: 0.2 | C10: Added to plan spend to size the raise | D10: Placeholder
A11: Gate 1 — Characterize complete (month) | B11: 9 | C11: Three-gate protocol milestone; drives tranche table | D11: Placeholder
A12: Gate 2 — Conservation test complete (month) | B12: 21 | D12: Placeholder
A13: Gate 3 — Extract or retire, published (month) | B13: 36 | D13: Placeholder
A14: Facility size (sq ft) | B14: 6000 | C14: Office + lab near UCI (University Research Park, Irvine) | D14: Placeholder
A15: Facility rate ($ per sq ft per month, full service) | B15: 3.75 | C15: Verify current University Research Park asking rates; lab-grade space runs higher | D15: Placeholder
A16: Facility rent (monthly) | B16: =B14*B15 -> 22500 | D16: Formula
A17: Security deposit (months of rent) | B17: 2 | D17: Placeholder
A18: Recruiting fee (% of first-year base, search firm) | B18: 0.2 | C18: Applied to the five applied-physicist hires | D18: Placeholder
A19: Outsourced finance (E57 or equivalent) — months 1–6 | B19: 25000 | C19: FP&A build + fractional controller, build phase; get E57's actual quote | D19: Placeholder
A20: Outsourced finance — month 7 onward | B20: 15000 | C20: Maintenance phase | D20: Placeholder
A21: Scenario name | B21: =CHOOSE(B4,"Lean","Base","Full") -> Base | D21: Formula

Sheet Headcount
A1: Headcount & consulting plan
A2: Blue = input. Start month = first month of cost (1 = model start). Equity is non-cash (cap table). 'Load?' = Y applies payroll load to base.
A3: ID | B3: Role | C3: Person / status | D3: Entity | E3: Type | F3: Annual base ($) | G3: Load? (Y/N) | H3: Relocation ($, one-time) | I3: Equity (non-cash) | J3: Start — Lean | K3: Start — Base | L3: Start — Full | M3: Start (selected) | N3: Monthly cost ($) | O3: 36-mo total ($) | P3: Discipline target / notes | Q3: Input status
A4: H01 | B4: Founder & CEO | C4: Ian F. McLean | D4: EnergyWave, Inc. | E4: W-2 | F4: 240000 | G4: Y | H4: 0 | I4: Founder | J4: 1 | K4: 1 | L4: 1 | M4: =CHOOSE(Scenario,J4,K4,L4) -> 1 | N4: =IF(G4="Y",F4*(1+LoadPct),F4)/12 -> 24400 | O4: =N4*MAX(0,Horizon-M4+1)+H4 -> 878400 | P4: Founder salary — set to an investor-acceptable level; pre-seed SAFE covered runway | Q4: Placeholder
A5: H02 | B5: Co-founder / Research Director (part-time) | C5: Kenneth "Chip" Story | D5: EnergyWave, Inc. | E5: 1099 | F5: 150000 | G5: N | H5: 0 | I5: Founder | J5: 1 | K5: 1 | L5: 1 | M5: =CHOOSE(Scenario,J5,K5,L5) -> 1 | N5: =IF(G5="Y",F5*(1+LoadPct),F5)/12 -> 12500 | O5: =N5*MAX(0,Horizon-M5+1)+H5 -> 450000 | P5: Confirm role, time commitment, cash vs. equity; document ZPEPG boundary (IP, conflicts) | Q5: Placeholder
A6: H03 | B6: Applied Physicist 1 | C6: Open requisition | D6: EnergyWave, Inc. | E6: W-2 | F6: 150000 | G6: Y | H6: =RelocDefault -> 25000 | I6: Pool | J6: 3 | K6: 2 | L6: 1 | M6: =CHOOSE(Scenario,J6,K6,L6) -> 2 | N6: =IF(G6="Y",F6*(1+LoadPct),F6)/12 -> 15250 | O6: =N6*MAX(0,Horizon-M6+1)+H6 -> 558750 | P6: Physics + mathematics + neuroscience (Ian's target mix) | Q6: From Ian (base); reloc placeholder
A7: H04 | B7: Applied Physicist 2 | C7: Open requisition | D7: EnergyWave, Inc. | E7: W-2 | F7: 150000 | G7: Y | H7: =RelocDefault -> 25000 | I7: Pool | J7: 4 | K7: 2 | L7: 1 | M7: =CHOOSE(Scenario,J7,K7,L7) -> 2 | N7: =IF(G7="Y",F7*(1+LoadPct),F7)/12 -> 15250 | O7: =N7*MAX(0,Horizon-M7+1)+H7 -> 558750 | P7: Physics + mechanical engineering + materials science | Q7: From Ian (base); reloc placeholder
A8: H05 | B8: Applied Physicist 3 | C8: Open requisition | D8: EnergyWave, Inc. | E8: W-2 | F8: 150000 | G8: Y | H8: =RelocDefault -> 25000 | I8: Pool | J8: 6 | K8: 3 | L8: 2 | M8: =CHOOSE(Scenario,J8,K8,L8) -> 3 | N8: =IF(G8="Y",F8*(1+LoadPct),F8)/12 -> 15250 | O8: =N8*MAX(0,Horizon-M8+1)+H8 -> 543500 | P8: Physics + materials science; calorimetry / thermal measurement | Q8: From Ian (base); reloc placeholder
A9: H06 | B9: Applied Physicist 4 | C9: Open requisition | D9: EnergyWave, Inc. | E9: W-2 | F9: 150000 | G9: Y | H9: =RelocDefault -> 25000 | I9: Pool | J9: 8 | K9: 4 | L9: 2 | M9: =CHOOSE(Scenario,J9,K9,L9) -> 4 | N9: =IF(G9="Y",F9*(1+LoadPct),F9)/12 -> 15250 | O9: =N9*MAX(0,Horizon-M9+1)+H9 -> 528250 | P9: Physics + electrical engineering; power electronics, precision measurement | Q9: From Ian (base); reloc placeholder
A10: H07 | B10: Applied Physicist 5 | C10: Open requisition | D10: EnergyWave, Inc. | E10: W-2 | F10: 150000 | G10: Y | H10: =RelocDefault -> 25000 | I10: Pool | J10: 10 | K10: 5 | L10: 3 | M10: =CHOOSE(Scenario,J10,K10,L10) -> 5 | N10: =IF(G10="Y",F10*(1+LoadPct),F10)/12 -> 15250 | O10: =N10*MAX(0,Horizon-M10+1)+H10 -> 513000 | P10: Physics + mathematics; statistics, null-result experimental design | Q10: From Ian (base); reloc placeholder
A11: H08 | B11: Theoretical Physicist — consulting agreement 1 | C11: Open | D11: EnergyWave, Inc. | E11: 1099 | F11: 500000 | G11: N | H11: 0 | I11: TBD | J11: 2 | K11: 1 | L11: 1 | M11: =CHOOSE(Scenario,J11,K11,L11) -> 1 | N11: =IF(G11="Y",F11*(1+LoadPct),F11)/12 -> 41666.667 | O11: =N11*MAX(0,Horizon-M11+1)+H11 -> 1500000 | P11: Ian: ~$500k/yr consulting agreement. Modeled as $500k EACH — confirm each vs. total | Q11: From Ian (interpretation flagged)
A12: H09 | B12: Theoretical Physicist — consulting agreement 2 | C12: Open | D12: EnergyWave, Inc. | E12: 1099 | F12: 500000 | G12: N | H12: 0 | I12: TBD | J12: 4 | K12: 3 | L12: 1 | M12: =CHOOSE(Scenario,J12,K12,L12) -> 3 | N12: =IF(G12="Y",F12*(1+LoadPct),F12)/12 -> 41666.667 | O12: =N12*MAX(0,Horizon-M12+1)+H12 -> 1416666.7 | P12: As above | Q12: From Ian (interpretation flagged)
A13: H10 | B13: Lab Safety / EHS Officer | C13: Open requisition | D13: EnergyWave, Inc. | E13: W-2 | F13: 120000 | G13: Y | H13: 10000 | I13: Pool | J13: 2 | K13: 1 | L13: 1 | M13: =CHOOSE(Scenario,J13,K13,L13) -> 1 | N13: =IF(G13="Y",F13*(1+LoadPct),F13)/12 -> 12200 | O13: =N13*MAX(0,Horizon-M13+1)+H13 -> 449200 | P13: Must precede lab operations; owns hazard review, test protocols, incident reporting | Q13: Placeholder
A14: H11 | B14: Test & Instrumentation Engineer 1 (calorimetry) | C14: Open requisition | D14: EnergyWave, Inc. | E14: W-2 | F14: 135000 | G14: Y | H14: 15000 | I14: Pool | J14: 3 | K14: 2 | L14: 1 | M14: =CHOOSE(Scenario,J14,K14,L14) -> 2 | N14: =IF(G14="Y",F14*(1+LoadPct),F14)/12 -> 13725 | O14: =N14*MAX(0,Horizon-M14+1)+H14 -> 495375 | P14: Calorimetry, DAQ, calibration discipline | Q14: Placeholder
A15: H12 | B15: Test & Instrumentation Engineer 2 | C15: Open requisition | D15: EnergyWave, Inc. | E15: W-2 | F15: 135000 | G15: Y | H15: 15000 | I15: Pool | J15: 6 | K15: 4 | L15: 2 | M15: =CHOOSE(Scenario,J15,K15,L15) -> 4 | N15: =IF(G15="Y",F15*(1+LoadPct),F15)/12 -> 13725 | O15: =N15*MAX(0,Horizon-M15+1)+H15 -> 467925 | P15: Second bench; independent replication of in-house measurements | Q15: Placeholder
A16: H13 | B16: Additive Manufacturing Engineer | C16: Open requisition | D16: EnergyWave, Inc. | E16: W-2 | F16: 140000 | G16: Y | H16: 15000 | I16: Pool | J16: 5 | K16: 3 | L16: 2 | M16: =CHOOSE(Scenario,J16,K16,L16) -> 3 | N16: =IF(G16="Y",F16*(1+LoadPct),F16)/12 -> 14233.333 | O16: =N16*MAX(0,Horizon-M16+1)+H16 -> 498933.33 | P16: Runs the precision AM system; process-parameter optimization | Q16: Placeholder
A17: H14 | B17: Software / Algorithms Engineer | C17: Open requisition | D17: EnergyWave, Inc. | E17: W-2 | F17: 160000 | G17: Y | H17: 15000 | I17: Pool | J17: 4 | K17: 3 | L17: 2 | M17: =CHOOSE(Scenario,J17,K17,L17) -> 3 | N17: =IF(G17="Y",F17*(1+LoadPct),F17)/12 -> 16266.667 | O17: =N17*MAX(0,Horizon-M17+1)+H17 -> 568066.67 | P17: Closed-loop AM parameter search, DAQ pipelines, data integrity / audit trail | Q17: Placeholder
A18: H15 | B18: Lab Technician | C18: Open requisition | D18: EnergyWave, Inc. | E18: W-2 | F18: 85000 | G18: Y | H18: 0 | I18: Pool | J18: 7 | K18: 4 | L18: 3 | M18: =CHOOSE(Scenario,J18,K18,L18) -> 4 | N18: =IF(G18="Y",F18*(1+LoadPct),F18)/12 -> 8641.6667 | O18: =N18*MAX(0,Horizon-M18+1)+H18 -> 285175 | Q18: Placeholder
A19: H16 | B19: Executive Assistant | C19: Open requisition | D19: EnergyWave, Inc. | E19: W-2 | F19: 85000 | G19: Y | H19: 0 | I19: Pool | J19: 2 | K19: 1 | L19: 1 | M19: =CHOOSE(Scenario,J19,K19,L19) -> 1 | N19: =IF(G19="Y",F19*(1+LoadPct),F19)/12 -> 8641.6667 | O19: =N19*MAX(0,Horizon-M19+1)+H19 -> 311100 | Q19: Placeholder
A20: H17 | B20: Office & Operations Coordinator | C20: Open requisition | D20: EnergyWave, Inc. | E20: W-2 | F20: 70000 | G20: Y | H20: 0 | I20: Pool | J20: 4 | K20: 2 | L20: 1 | M20: =CHOOSE(Scenario,J20,K20,L20) -> 2 | N20: =IF(G20="Y",F20*(1+LoadPct),F20)/12 -> 7116.6667 | O20: =N20*MAX(0,Horizon-M20+1)+H20 -> 249083.33 | Q20: Placeholder
A21: H18 | B21: Government Liaison (consulting) | C21: Eric Fitzgerald | D21: EnergyWave, Inc. | E21: 1099 | F21: 60000 | G21: N | H21: 0 | I21: TBD | J21: 2 | K21: 1 | L21: 1 | M21: =CHOOSE(Scenario,J21,K21,L21) -> 1 | N21: =IF(G21="Y",F21*(1+LoadPct),F21)/12 -> 5000 | O21: =N21*MAX(0,Horizon-M21+1)+H21 -> 180000 | P21: Confirm engagement terms (cash vs. equity); lobbying-disclosure check | Q21: Placeholder
B22: Total | F22: =SUM(F4:F21) -> 3130000 | H22: =SUM(H4:H21) -> 195000 | N22: =SUM(N4:N21) -> 296033.33 | O22: =SUM(O4:O21) -> 10452175
B24: Legend: Start month is the first month the cost hits. Monthly cost = base × (1 + load) / 12 for W-2, base / 12 for 1099. 36-mo total = monthly × months remaining + relocation.
B25: Equity: 'Pool' = grant from the option pool (Assumptions!B9); 'Founder' = founder stock; 'TBD' = advisor/consultant grant to be decided. None of this is cash.

Sheet CostLines
A1: Non-payroll cost lines (facilities, equipment, research, legal, finance, G&A)
A2: Blue = input. Type: Monthly (recurs from start), One-time (hits start month only), Annual (spread 1/12 per month from start). Blank duration = through horizon.
A3: ID | B3: Line item | C3: Entity | D3: Category | E3: Subcategory | F3: Type | G3: Lean ($) | H3: Base ($) | I3: Full ($) | J3: Selected ($) | K3: Start — Lean | L3: Start — Base | M3: Start — Full | N3: Start (selected) | O3: Duration (months; blank = to end) | P3: Monthly equiv. ($) | Q3: 36-mo total ($) | R3: Notes | S3: Input status
A4: C01 | B4: Office + lab lease near UCI (University Research Park) | C4: EnergyWave, Inc. | D4: Facilities | E4: Lease | F4: Monthly | G4: =RentMonthly -> 22500 | H4: =RentMonthly -> 22500 | I4: =RentMonthly -> 22500 | J4: =CHOOSE(Scenario,G4,H4,I4) -> 22500 | K4: 3 | L4: 2 | M4: 1 | N4: =CHOOSE(Scenario,K4,L4,M4) -> 2 | P4: =IF(F4="Monthly",J4,IF(F4="Annual",J4/12,0)) -> 22500 | Q4: =IF(F4="One-time",IF(N4<=Horizon,J4,0),P4*MAX(0,MIN(Horizon,IF(O4="",Horizon,N4+O4-1))-N4+1)) -> 787500 | R4: 6,000 sf × $3.75/sf/mo full service (Assumptions). Lab-grade space with power/ventilation may price higher. | S4: Placeholder
A5: C02 | B5: Security deposit | C5: EnergyWave, Inc. | D5: Facilities | E5: Deposit | F5: One-time | G5: =RentMonthly*DepositMonths -> 45000 | H5: =RentMonthly*DepositMonths -> 45000 | I5: =RentMonthly*DepositMonths -> 45000 | J5: =CHOOSE(Scenario,G5,H5,I5) -> 45000 | K5: 3 | L5: 2 | M5: 1 | N5: =CHOOSE(Scenario,K5,L5,M5) -> 2 | P5: =IF(F5="Monthly",J5,IF(F5="Annual",J5/12,0)) -> 0 | Q5: =IF(F5="One-time",IF(N5<=Horizon,J5,0),P5*MAX(0,MIN(Horizon,IF(O5="",Horizon,N5+O5-1))-N5+1)) -> 45000 | R5: Months of rent per Assumptions | S5: Formula
A6: C03 | B6: Lab build-out (power, ventilation, benches, shielding) | C6: EnergyWave, Inc. | D6: Facilities | E6: Build-out | F6: One-time | G6: 150000 | H6: 300000 | I6: 600000 | J6: =CHOOSE(Scenario,G6,H6,I6) -> 300000 | K6: 3 | L6: 2 | M6: 1 | N6: =CHOOSE(Scenario,K6,L6,M6) -> 2 | P6: =IF(F6="Monthly",J6,IF(F6="Annual",J6/12,0)) -> 0 | Q6: =IF(F6="One-time",IF(N6<=Horizon,J6,0),P6*MAX(0,MIN(Horizon,IF(O6="",Horizon,N6+O6-1))-N6+1)) -> 300000 | R6: Tenant-improvement scope TBD with landlord; partly offsettable by TI allowance | S6: Placeholder
A7: C04 | B7: Utilities, internet, security | C7: EnergyWave, Inc. | D7: Facilities | E7: Utilities | F7: Monthly | G7: 3000 | H7: 4000 | I7: 6000 | J7: =CHOOSE(Scenario,G7,H7,I7) -> 4000 | K7: 3 | L7: 2 | M7: 1 | N7: =CHOOSE(Scenario,K7,L7,M7) -> 2 | P7: =IF(F7="Monthly",J7,IF(F7="Annual",J7/12,0)) -> 4000 | Q7: =IF(F7="One-time",IF(N7<=Horizon,J7,0),P7*MAX(0,MIN(Horizon,IF(O7="",Horizon,N7+O7-1))-N7+1)) -> 140000 | S7: Placeholder
A8: C05 | B8: Tabletop instrumentation package (calorimeters, power analyzers, precision sources/loads, DAQ, thermal chambers, balances, shielded enclosure, reference standards) | C8: EnergyWave, Inc. | D8: Equipment | E8: Instrumentation | F8: One-time | G8: 250000 | H8: 450000 | I8: 750000 | J8: =CHOOSE(Scenario,G8,H8,I8) -> 450000 | K8: 3 | L8: 2 | M8: 1 | N8: =CHOOSE(Scenario,K8,L8,M8) -> 2 | P8: =IF(F8="Monthly",J8,IF(F8="Annual",J8/12,0)) -> 0 | Q8: =IF(F8="One-time",IF(N8<=Horizon,J8,0),P8*MAX(0,MIN(Horizon,IF(O8="",Horizon,N8+O8-1))-N8+1)) -> 450000 | R8: Package, not a spec list. Priced for conservation-of-energy measurement, not for any device claim. | S8: Placeholder
A9: C06 | B9: Calibration & metrology services | C9: EnergyWave, Inc. | D9: Equipment | E9: Calibration | F9: Annual | G9: 20000 | H9: 30000 | I9: 45000 | J9: =CHOOSE(Scenario,G9,H9,I9) -> 30000 | K9: 4 | L9: 3 | M9: 2 | N9: =CHOOSE(Scenario,K9,L9,M9) -> 3 | P9: =IF(F9="Monthly",J9,IF(F9="Annual",J9/12,0)) -> 2500 | Q9: =IF(F9="One-time",IF(N9<=Horizon,J9,0),P9*MAX(0,MIN(Horizon,IF(O9="",Horizon,N9+O9-1))-N9+1)) -> 85000 | R9: Traceable calibration is what makes a null result publishable | S9: Placeholder
A10: C07 | B10: Precision additive-manufacturing system (high-resolution AM with closed-loop process control) | C10: EnergyWave, Inc. | D10: Equipment | E10: Additive manufacturing | F10: One-time | G10: 350000 | H10: 750000 | I10: 1500000 | J10: =CHOOSE(Scenario,G10,H10,I10) -> 750000 | K10: 5 | L10: 3 | M10: 2 | N10: =CHOOSE(Scenario,K10,L10,M10) -> 3 | P10: =IF(F10="Monthly",J10,IF(F10="Annual",J10/12,0)) -> 0 | Q10: =IF(F10="One-time",IF(N10<=Horizon,J10,0),P10*MAX(0,MIN(Horizon,IF(O10="",Horizon,N10+O10-1))-N10+1)) -> 750000 | R10: Class/vendor TBD (micro-scale polymer/metal vs. metal laser powder-bed). Placeholder = mid-range list price. | S10: Placeholder
A11: C08 | B11: AM service contract & software | C11: EnergyWave, Inc. | D11: Equipment | E11: Additive manufacturing | F11: Annual | G11: 30000 | H11: 40000 | I11: 60000 | J11: =CHOOSE(Scenario,G11,H11,I11) -> 40000 | K11: 6 | L11: 4 | M11: 3 | N11: =CHOOSE(Scenario,K11,L11,M11) -> 4 | P11: =IF(F11="Monthly",J11,IF(F11="Annual",J11/12,0)) -> 3333.3333 | Q11: =IF(F11="One-time",IF(N11<=Horizon,J11,0),P11*MAX(0,MIN(Horizon,IF(O11="",Horizon,N11+O11-1))-N11+1)) -> 110000 | S11: Placeholder
A12: C09 | B12: AM feedstock & lab consumables | C12: EnergyWave, Inc. | D12: Operations | E12: Consumables | F12: Monthly | G12: 6000 | H12: 10000 | I12: 16000 | J12: =CHOOSE(Scenario,G12,H12,I12) -> 10000 | K12: 4 | L12: 3 | M12: 2 | N12: =CHOOSE(Scenario,K12,L12,M12) -> 3 | P12: =IF(F12="Monthly",J12,IF(F12="Annual",J12/12,0)) -> 10000 | Q12: =IF(F12="One-time",IF(N12<=Horizon,J12,0),P12*MAX(0,MIN(Horizon,IF(O12="",Horizon,N12+O12-1))-N12+1)) -> 340000 | S12: Placeholder
A13: C10 | B13: Compute, simulation & software licenses | C13: EnergyWave, Inc. | D13: Operations | E13: Compute | F13: Monthly | G13: 5000 | H13: 8000 | I13: 12000 | J13: =CHOOSE(Scenario,G13,H13,I13) -> 8000 | K13: 1 | L13: 1 | M13: 1 | N13: =CHOOSE(Scenario,K13,L13,M13) -> 1 | P13: =IF(F13="Monthly",J13,IF(F13="Annual",J13/12,0)) -> 8000 | Q13: =IF(F13="One-time",IF(N13<=Horizon,J13,0),P13*MAX(0,MIN(Horizon,IF(O13="",Horizon,N13+O13-1))-N13+1)) -> 288000 | S13: Placeholder
A14: C11 | B14: Independent third-party replication / verification | C14: EnergyWave, Inc. | D14: Research | E14: External verification | F14: Annual | G14: 100000 | H14: 150000 | I14: 250000 | J14: =CHOOSE(Scenario,G14,H14,I14) -> 150000 | K14: 9 | L14: 7 | M14: 5 | N14: =CHOOSE(Scenario,K14,L14,M14) -> 7 | P14: =IF(F14="Monthly",J14,IF(F14="Annual",J14/12,0)) -> 12500 | Q14: =IF(F14="One-time",IF(N14<=Horizon,J14,0),P14*MAX(0,MIN(Horizon,IF(O14="",Horizon,N14+O14-1))-N14+1)) -> 375000 | R14: Core to claims discipline; results published either direction | S14: Placeholder
A15: C12 | B15: UCI / NFCRC facility-use or sponsored-research agreement | C15: EnergyWave, Inc. | D15: Research | E15: University partnership | F15: Annual | G15: 75000 | H15: 150000 | I15: 300000 | J15: =CHOOSE(Scenario,G15,H15,I15) -> 150000 | K15: 4 | L15: 3 | M15: 2 | N15: =CHOOSE(Scenario,K15,L15,M15) -> 3 | P15: =IF(F15="Monthly",J15,IF(F15="Annual",J15/12,0)) -> 12500 | Q15: =IF(F15="One-time",IF(N15<=Horizon,J15,0),P15*MAX(0,MIN(Horizon,IF(O15="",Horizon,N15+O15-1))-N15+1)) -> 425000 | R15: Only exists if an agreement is executed; proximity alone offsets nothing. Also the STTR path. | S15: Placeholder
A16: C13 | B16: K&L Gates IP retainer (Novak / Majewski) | C16: EnergyWave, Inc. | D16: Legal | E16: IP | F16: Monthly | G16: 10000 | H16: 15000 | I16: 20000 | J16: =CHOOSE(Scenario,G16,H16,I16) -> 15000 | K16: 1 | L16: 1 | M16: 1 | N16: =CHOOSE(Scenario,K16,L16,M16) -> 1 | P16: =IF(F16="Monthly",J16,IF(F16="Annual",J16/12,0)) -> 15000 | Q16: =IF(F16="One-time",IF(N16<=Horizon,J16,0),P16*MAX(0,MIN(Horizon,IF(O16="",Horizon,N16+O16-1))-N16+1)) -> 540000 | R16: Confirm current retainer terms | S16: Placeholder
A17: C14 | B17: Entity work: 501(c)(3) determinations, intercompany / services agreements | C17: EnergyWave, Inc. | D17: Legal | E17: Corporate | F17: One-time | G17: 40000 | H17: 60000 | I17: 90000 | J17: =CHOOSE(Scenario,G17,H17,I17) -> 60000 | K17: 1 | L17: 1 | M17: 1 | N17: =CHOOSE(Scenario,K17,L17,M17) -> 1 | P17: =IF(F17="Monthly",J17,IF(F17="Annual",J17/12,0)) -> 0 | Q17: =IF(F17="One-time",IF(N17<=Horizon,J17,0),P17*MAX(0,MIN(Horizon,IF(O17="",Horizon,N17+O17-1))-N17+1)) -> 60000 | R17: Covers EW share only; nonprofits fund their own | S17: Placeholder
A18: C15 | B18: Securities counsel (raise docs, Wyoming pooling LLC, SAFE conversion) | C18: EnergyWave, Inc. | D18: Legal | E18: Securities | F18: One-time | G18: 50000 | H18: 75000 | I18: 125000 | J18: =CHOOSE(Scenario,G18,H18,I18) -> 75000 | K18: 1 | L18: 1 | M18: 1 | N18: =CHOOSE(Scenario,K18,L18,M18) -> 1 | P18: =IF(F18="Monthly",J18,IF(F18="Annual",J18/12,0)) -> 0 | Q18: =IF(F18="One-time",IF(N18<=Horizon,J18,0),P18*MAX(0,MIN(Horizon,IF(O18="",Horizon,N18+O18-1))-N18+1)) -> 75000 | R18: Joseph Johnson | S18: Placeholder
A19: C16 | B19: Ongoing corporate / employment counsel | C19: EnergyWave, Inc. | D19: Legal | E19: Corporate | F19: Monthly | G19: 3000 | H19: 5000 | I19: 8000 | J19: =CHOOSE(Scenario,G19,H19,I19) -> 5000 | K19: 2 | L19: 1 | M19: 1 | N19: =CHOOSE(Scenario,K19,L19,M19) -> 1 | P19: =IF(F19="Monthly",J19,IF(F19="Annual",J19/12,0)) -> 5000 | Q19: =IF(F19="One-time",IF(N19<=Horizon,J19,0),P19*MAX(0,MIN(Horizon,IF(O19="",Horizon,N19+O19-1))-N19+1)) -> 180000 | S19: Placeholder
A20: C17 | B20: Outsourced finance (E57 or equivalent) — build phase | C20: EnergyWave, Inc. | D20: Finance | E20: Outsourced finance | F20: Monthly | G20: =FinPhase1 -> 25000 | H20: =FinPhase1 -> 25000 | I20: =FinPhase1 -> 25000 | J20: =CHOOSE(Scenario,G20,H20,I20) -> 25000 | K20: 1 | L20: 1 | M20: 1 | N20: =CHOOSE(Scenario,K20,L20,M20) -> 1 | O20: 6 | P20: =IF(F20="Monthly",J20,IF(F20="Annual",J20/12,0)) -> 25000 | Q20: =IF(F20="One-time",IF(N20<=Horizon,J20,0),P20*MAX(0,MIN(Horizon,IF(O20="",Horizon,N20+O20-1))-N20+1)) -> 150000 | R20: Interim FP&A + fractional controller; replace with E57's quote | S20: Placeholder
A21: C18 | B21: Outsourced finance (E57 or equivalent) — maintenance | C21: EnergyWave, Inc. | D21: Finance | E21: Outsourced finance | F21: Monthly | G21: =FinPhase2 -> 15000 | H21: =FinPhase2 -> 15000 | I21: =FinPhase2 -> 15000 | J21: =CHOOSE(Scenario,G21,H21,I21) -> 15000 | K21: 7 | L21: 7 | M21: 7 | N21: =CHOOSE(Scenario,K21,L21,M21) -> 7 | P21: =IF(F21="Monthly",J21,IF(F21="Annual",J21/12,0)) -> 15000 | Q21: =IF(F21="One-time",IF(N21<=Horizon,J21,0),P21*MAX(0,MIN(Horizon,IF(O21="",Horizon,N21+O21-1))-N21+1)) -> 450000 | S21: Placeholder
A22: C19 | B22: Audit, tax, Form 990 support (affiliates billed separately) | C22: EnergyWave, Inc. | D22: Finance | E22: Audit & tax | F22: Annual | G22: 30000 | H22: 40000 | I22: 60000 | J22: =CHOOSE(Scenario,G22,H22,I22) -> 40000 | K22: 12 | L22: 12 | M22: 12 | N22: =CHOOSE(Scenario,K22,L22,M22) -> 12 | P22: =IF(F22="Monthly",J22,IF(F22="Annual",J22/12,0)) -> 3333.3333 | Q22: =IF(F22="One-time",IF(N22<=Horizon,J22,0),P22*MAX(0,MIN(Horizon,IF(O22="",Horizon,N22+O22-1))-N22+1)) -> 83333.333 | S22: Placeholder
A23: C20 | B23: Accounting / HR / cap-table systems (QuickBooks or NetSuite, payroll, Carta) | C23: EnergyWave, Inc. | D23: Finance | E23: Systems | F23: Monthly | G23: 800 | H23: 1500 | I23: 3000 | J23: =CHOOSE(Scenario,G23,H23,I23) -> 1500 | K23: 1 | L23: 1 | M23: 1 | N23: =CHOOSE(Scenario,K23,L23,M23) -> 1 | P23: =IF(F23="Monthly",J23,IF(F23="Annual",J23/12,0)) -> 1500 | Q23: =IF(F23="One-time",IF(N23<=Horizon,J23,0),P23*MAX(0,MIN(Horizon,IF(O23="",Horizon,N23+O23-1))-N23+1)) -> 54000 | S23: Placeholder
A24: C21 | B24: Insurance (D&O, GL, property, testing liability, workers' comp) | C24: EnergyWave, Inc. | D24: G&A | E24: Insurance | F24: Annual | G24: 60000 | H24: 90000 | I24: 140000 | J24: =CHOOSE(Scenario,G24,H24,I24) -> 90000 | K24: 1 | L24: 1 | M24: 1 | N24: =CHOOSE(Scenario,K24,L24,M24) -> 1 | P24: =IF(F24="Monthly",J24,IF(F24="Annual",J24/12,0)) -> 7500 | Q24: =IF(F24="One-time",IF(N24<=Horizon,J24,0),P24*MAX(0,MIN(Horizon,IF(O24="",Horizon,N24+O24-1))-N24+1)) -> 270000 | R24: Broker quote needed; lab operations drive the property/liability lines | S24: Placeholder
A25: C22 | B25: Recruiting — search fees, five applied physicists | C25: EnergyWave, Inc. | D25: G&A | E25: Recruiting | F25: One-time | G25: =RecruitFeePct*SUM(Headcount!$F$6:$F$10) -> 150000 | H25: =RecruitFeePct*SUM(Headcount!$F$6:$F$10) -> 150000 | I25: =RecruitFeePct*SUM(Headcount!$F$6:$F$10) -> 150000 | J25: =CHOOSE(Scenario,G25,H25,I25) -> 150000 | K25: 2 | L25: 1 | M25: 1 | N25: =CHOOSE(Scenario,K25,L25,M25) -> 1 | P25: =IF(F25="Monthly",J25,IF(F25="Annual",J25/12,0)) -> 0 | Q25: =IF(F25="One-time",IF(N25<=Horizon,J25,0),P25*MAX(0,MIN(Horizon,IF(O25="",Horizon,N25+O25-1))-N25+1)) -> 150000 | R25: Recruiting fee % × first-year base (H03–H07) | S25: Formula
A26: C23 | B26: Recruiting — other roles | C26: EnergyWave, Inc. | D26: G&A | E26: Recruiting | F26: One-time | G26: 30000 | H26: 50000 | I26: 80000 | J26: =CHOOSE(Scenario,G26,H26,I26) -> 50000 | K26: 2 | L26: 1 | M26: 1 | N26: =CHOOSE(Scenario,K26,L26,M26) -> 1 | P26: =IF(F26="Monthly",J26,IF(F26="Annual",J26/12,0)) -> 0 | Q26: =IF(F26="One-time",IF(N26<=Horizon,J26,0),P26*MAX(0,MIN(Horizon,IF(O26="",Horizon,N26+O26-1))-N26+1)) -> 50000 | S26: Placeholder
A27: C24 | B27: Travel & government engagement | C27: EnergyWave, Inc. | D27: G&A | E27: Travel | F27: Monthly | G27: 4000 | H27: 8000 | I27: 12000 | J27: =CHOOSE(Scenario,G27,H27,I27) -> 8000 | K27: 1 | L27: 1 | M27: 1 | N27: =CHOOSE(Scenario,K27,L27,M27) -> 1 | P27: =IF(F27="Monthly",J27,IF(F27="Annual",J27/12,0)) -> 8000 | Q27: =IF(F27="One-time",IF(N27<=Horizon,J27,0),P27*MAX(0,MIN(Horizon,IF(O27="",Horizon,N27+O27-1))-N27+1)) -> 288000 | S27: Placeholder
A28: C25 | B28: Publications, null-results registry, conferences | C28: EnergyWave, Inc. | D28: Research | E28: Dissemination | F28: Monthly | G28: 1500 | H28: 3000 | I28: 5000 | J28: =CHOOSE(Scenario,G28,H28,I28) -> 3000 | K28: 3 | L28: 2 | M28: 1 | N28: =CHOOSE(Scenario,K28,L28,M28) -> 2 | P28: =IF(F28="Monthly",J28,IF(F28="Annual",J28/12,0)) -> 3000 | Q28: =IF(F28="One-time",IF(N28<=Horizon,J28,0),P28*MAX(0,MIN(Horizon,IF(O28="",Horizon,N28+O28-1))-N28+1)) -> 105000 | S28: Placeholder
A29: C26 | B29: Office equipment & IT hardware | C29: EnergyWave, Inc. | D29: G&A | E29: Office | F29: One-time | G29: 40000 | H29: 70000 | I29: 120000 | J29: =CHOOSE(Scenario,G29,H29,I29) -> 70000 | K29: 3 | L29: 2 | M29: 1 | N29: =CHOOSE(Scenario,K29,L29,M29) -> 2 | P29: =IF(F29="Monthly",J29,IF(F29="Annual",J29/12,0)) -> 0 | Q29: =IF(F29="One-time",IF(N29<=Horizon,J29,0),P29*MAX(0,MIN(Horizon,IF(O29="",Horizon,N29+O29-1))-N29+1)) -> 70000 | S29: Placeholder
A30: C27 | B30: Intercompany services to/from GovThink Institute & pinnacle.blog (arms-length) | C30: EnergyWave, Inc. | D30: Intercompany | E30: Affiliates | F30: Monthly | G30: 0 | H30: 0 | I30: 0 | J30: =CHOOSE(Scenario,G30,H30,I30) -> 0 | K30: 1 | L30: 1 | M30: 1 | N30: =CHOOSE(Scenario,K30,L30,M30) -> 1 | P30: =IF(F30="Monthly",J30,IF(F30="Annual",J30/12,0)) -> 0 | Q30: =IF(F30="One-time",IF(N30<=Horizon,J30,0),P30*MAX(0,MIN(Horizon,IF(O30="",Horizon,N30+O30-1))-N30+1)) -> 0 | R30: BLOCKED — do not populate until Novak confirms structure; any services priced at FMV under written agreement | S30: Blocked
B31: Total (selected scenario, 36 months) | Q31: =SUM(Q4:Q30) -> 6620833.3

Sheet Monthly
A1: Monthly cash-need engine (36 months)
A2: Scenario: | B2: =ScenarioName -> Base | D2: All rows pull from Headcount and CostLines; edit inputs there, not here.
A4: Line | B4: Entity | C4: Category | D4: Subcategory | E4: 36-mo total ($) | F4: 1 | G4: 2 | H4: 3 | I4: 4 | J4: 5 | K4: 6 | L4: 7 | M4: 8 | N4: 9 | O4: 10 | P4: 11 | Q4: 12 | R4: 13 | S4: 14 | T4: 15 | U4: 16 | V4: 17 | W4: 18 | X4: 19 | Y4: 20 | Z4: 21 | AA4: 22 | AB4: 23 | AC4: 24 | AD4: 25 | AE4: 26 | AF4: 27 | AG4: 28 | AH4: 29 | AI4: 30 | AJ4: 31 | AK4: 32 | AL4: 33 | AM4: 34 | AN4: 35 | AO4: 36
E5: Month | F5: =EDATE(StartDate,F$4-1) -> 46388 | G5: =EDATE(StartDate,G$4-1) -> 46419 | H5: =EDATE(StartDate,H$4-1) -> 46447 | I5: =EDATE(StartDate,I$4-1) -> 46478 | J5: =EDATE(StartDate,J$4-1) -> 46508 | K5: =EDATE(StartDate,K$4-1) -> 46539 | L5: =EDATE(StartDate,L$4-1) -> 46569 | M5: =EDATE(StartDate,M$4-1) -> 46600 | ... AO5: =EDATE(StartDate,AO$4-1) -> 47453
E6: Gate | F6: =IF(F$4=Gate1,"G1",IF(F$4=Gate2,"G2",IF(F$4=Gate3,"G3",""))) | G6: =IF(G$4=Gate1,"G1",IF(G$4=Gate2,"G2",IF(G$4=Gate3,"G3",""))) | H6: =IF(H$4=Gate1,"G1",IF(H$4=Gate2,"G2",IF(H$4=Gate3,"G3",""))) | I6: =IF(I$4=Gate1,"G1",IF(I$4=Gate2,"G2",IF(I$4=Gate3,"G3",""))) | J6: =IF(J$4=Gate1,"G1",IF(J$4=Gate2,"G2",IF(J$4=Gate3,"G3",""))) | K6: =IF(K$4=Gate1,"G1",IF(K$4=Gate2,"G2",IF(K$4=Gate3,"G3",""))) | L6: =IF(L$4=Gate1,"G1",IF(L$4=Gate2,"G2",IF(L$4=Gate3,"G3",""))) | M6: =IF(M$4=Gate1,"G1",IF(M$4=Gate2,"G2",IF(M$4=Gate3,"G3",""))) | ... AO6: =IF(AO$4=Gate1,"G1",IF(AO$4=Gate2,"G2",IF(AO$4=Gate3,"G3",""))) -> G3
A7: PEOPLE (from Headcount)
A8: =Headcount!B4 -> Founder & CEO | B8: =Headcount!D4 -> EnergyWave, Inc. | C8: =IF(Headcount!E4="W-2","Payroll","Consulting") -> Payroll | D8: =IF(Headcount!E4="W-2","Salary & load","Consulting fee") -> Salary & load | E8: =SUM(F8:AO8) -> 878400 | F8: =IF(F$4>=Headcount!$M4,Headcount!$N4,0) -> 24400 | G8: =IF(G$4>=Headcount!$M4,Headcount!$N4,0) -> 24400 | H8: =IF(H$4>=Headcount!$M4,Headcount!$N4,0) -> 24400 | I8: =IF(I$4>=Headcount!$M4,Headcount!$N4,0) -> 24400 | J8: =IF(J$4>=Headcount!$M4,Headcount!$N4,0) -> 24400 | K8: =IF(K$4>=Headcount!$M4,Headcount!$N4,0) -> 24400 | L8: =IF(L$4>=Headcount!$M4,Headcount!$N4,0) -> 24400 | M8: =IF(M$4>=Headcount!$M4,Headcount!$N4,0) -> 24400 | ... AO8: =IF(AO$4>=Headcount!$M4,Headcount!$N4,0) -> 24400
A9: =Headcount!B5 -> Co-founder / Research Director (part-time) | B9: =Headcount!D5 -> EnergyWave, Inc. | C9: =IF(Headcount!E5="W-2","Payroll","Consulting") -> Consulting | D9: =IF(Headcount!E5="W-2","Salary & load","Consulting fee") -> Consulting fee | E9: =SUM(F9:AO9) -> 450000 | F9: =IF(F$4>=Headcount!$M5,Headcount!$N5,0) -> 12500 | G9: =IF(G$4>=Headcount!$M5,Headcount!$N5,0) -> 12500 | H9: =IF(H$4>=Headcount!$M5,Headcount!$N5,0) -> 12500 | I9: =IF(I$4>=Headcount!$M5,Headcount!$N5,0) -> 12500 | J9: =IF(J$4>=Headcount!$M5,Headcount!$N5,0) -> 12500 | K9: =IF(K$4>=Headcount!$M5,Headcount!$N5,0) -> 12500 | L9: =IF(L$4>=Headcount!$M5,Headcount!$N5,0) -> 12500 | M9: =IF(M$4>=Headcount!$M5,Headcount!$N5,0) -> 12500 | ... AO9: =IF(AO$4>=Headcount!$M5,Headcount!$N5,0) -> 12500
A10: =Headcount!B6 -> Applied Physicist 1 | B10: =Headcount!D6 -> EnergyWave, Inc. | C10: =IF(Headcount!E6="W-2","Payroll","Consulting") -> Payroll | D10: =IF(Headcount!E6="W-2","Salary & load","Consulting fee") -> Salary & load | E10: =SUM(F10:AO10) -> 533750 | F10: =IF(F$4>=Headcount!$M6,Headcount!$N6,0) -> 0 | G10: =IF(G$4>=Headcount!$M6,Headcount!$N6,0) -> 15250 | H10: =IF(H$4>=Headcount!$M6,Headcount!$N6,0) -> 15250 | I10: =IF(I$4>=Headcount!$M6,Headcount!$N6,0) -> 15250 | J10: =IF(J$4>=Headcount!$M6,Headcount!$N6,0) -> 15250 | K10: =IF(K$4>=Headcount!$M6,Headcount!$N6,0) -> 15250 | L10: =IF(L$4>=Headcount!$M6,Headcount!$N6,0) -> 15250 | M10: =IF(M$4>=Headcount!$M6,Headcount!$N6,0) -> 15250 | ... AO10: =IF(AO$4>=Headcount!$M6,Headcount!$N6,0) -> 15250
A11: =Headcount!B7 -> Applied Physicist 2 | B11: =Headcount!D7 -> EnergyWave, Inc. | C11: =IF(Headcount!E7="W-2","Payroll","Consulting") -> Payroll | D11: =IF(Headcount!E7="W-2","Salary & load","Consulting fee") -> Salary & load | E11: =SUM(F11:AO11) -> 533750 | F11: =IF(F$4>=Headcount!$M7,Headcount!$N7,0) -> 0 | G11: =IF(G$4>=Headcount!$M7,Headcount!$N7,0) -> 15250 | H11: =IF(H$4>=Headcount!$M7,Headcount!$N7,0) -> 15250 | I11: =IF(I$4>=Headcount!$M7,Headcount!$N7,0) -> 15250 | J11: =IF(J$4>=Headcount!$M7,Headcount!$N7,0) -> 15250 | K11: =IF(K$4>=Headcount!$M7,Headcount!$N7,0) -> 15250 | L11: =IF(L$4>=Headcount!$M7,Headcount!$N7,0) -> 15250 | M11: =IF(M$4>=Headcount!$M7,Headcount!$N7,0) -> 15250 | ... AO11: =IF(AO$4>=Headcount!$M7,Headcount!$N7,0) -> 15250
A12: =Headcount!B8 -> Applied Physicist 3 | B12: =Headcount!D8 -> EnergyWave, Inc. | C12: =IF(Headcount!E8="W-2","Payroll","Consulting") -> Payroll | D12: =IF(Headcount!E8="W-2","Salary & load","Consulting fee") -> Salary & load | E12: =SUM(F12:AO12) -> 518500 | F12: =IF(F$4>=Headcount!$M8,Headcount!$N8,0) -> 0 | G12: =IF(G$4>=Headcount!$M8,Headcount!$N8,0) -> 0 | H12: =IF(H$4>=Headcount!$M8,Headcount!$N8,0) -> 15250 | I12: =IF(I$4>=Headcount!$M8,Headcount!$N8,0) -> 15250 | J12: =IF(J$4>=Headcount!$M8,Headcount!$N8,0) -> 15250 | K12: =IF(K$4>=Headcount!$M8,Headcount!$N8,0) -> 15250 | L12: =IF(L$4>=Headcount!$M8,Headcount!$N8,0) -> 15250 | M12: =IF(M$4>=Headcount!$M8,Headcount!$N8,0) -> 15250 | ... AO12: =IF(AO$4>=Headcount!$M8,Headcount!$N8,0) -> 15250
A13: =Headcount!B9 -> Applied Physicist 4 | B13: =Headcount!D9 -> EnergyWave, Inc. | C13: =IF(Headcount!E9="W-2","Payroll","Consulting") -> Payroll | D13: =IF(Headcount!E9="W-2","Salary & load","Consulting fee") -> Salary & load | E13: =SUM(F13:AO13) -> 503250 | F13: =IF(F$4>=Headcount!$M9,Headcount!$N9,0) -> 0 | G13: =IF(G$4>=Headcount!$M9,Headcount!$N9,0) -> 0 | H13: =IF(H$4>=Headcount!$M9,Headcount!$N9,0) -> 0 | I13: =IF(I$4>=Headcount!$M9,Headcount!$N9,0) -> 15250 | J13: =IF(J$4>=Headcount!$M9,Headcount!$N9,0) -> 15250 | K13: =IF(K$4>=Headcount!$M9,Headcount!$N9,0) -> 15250 | L13: =IF(L$4>=Headcount!$M9,Headcount!$N9,0) -> 15250 | M13: =IF(M$4>=Headcount!$M9,Headcount!$N9,0) -> 15250 | ... AO13: =IF(AO$4>=Headcount!$M9,Headcount!$N9,0) -> 15250
A14: =Headcount!B10 -> Applied Physicist 5 | B14: =Headcount!D10 -> EnergyWave, Inc. | C14: =IF(Headcount!E10="W-2","Payroll","Consulting") -> Payroll | D14: =IF(Headcount!E10="W-2","Salary & load","Consulting fee") -> Salary & load | E14: =SUM(F14:AO14) -> 488000 | F14: =IF(F$4>=Headcount!$M10,Headcount!$N10,0) -> 0 | G14: =IF(G$4>=Headcount!$M10,Headcount!$N10,0) -> 0 | H14: =IF(H$4>=Headcount!$M10,Headcount!$N10,0) -> 0 | I14: =IF(I$4>=Headcount!$M10,Headcount!$N10,0) -> 0 | J14: =IF(J$4>=Headcount!$M10,Headcount!$N10,0) -> 15250 | K14: =IF(K$4>=Headcount!$M10,Headcount!$N10,0) -> 15250 | L14: =IF(L$4>=Headcount!$M10,Headcount!$N10,0) -> 15250 | M14: =IF(M$4>=Headcount!$M10,Headcount!$N10,0) -> 15250 | ... AO14: =IF(AO$4>=Headcount!$M10,Headcount!$N10,0) -> 15250
A15: =Headcount!B11 -> Theoretical Physicist — consulting agreement 1 | B15: =Headcount!D11 -> EnergyWave, Inc. | C15: =IF(Headcount!E11="W-2","Payroll","Consulting") -> Consulting | D15: =IF(Headcount!E11="W-2","Salary & load","Consulting fee") -> Consulting fee | E15: =SUM(F15:AO15) -> 1500000 | F15: =IF(F$4>=Headcount!$M11,Headcount!$N11,0) -> 41666.667 | G15: =IF(G$4>=Headcount!$M11,Headcount!$N11,0) -> 41666.667 | H15: =IF(H$4>=Headcount!$M11,Headcount!$N11,0) -> 41666.667 | I15: =IF(I$4>=Headcount!$M11,Headcount!$N11,0) -> 41666.667 | J15: =IF(J$4>=Headcount!$M11,Headcount!$N11,0) -> 41666.667 | K15: =IF(K$4>=Headcount!$M11,Headcount!$N11,0) -> 41666.667 | L15: =IF(L$4>=Headcount!$M11,Headcount!$N11,0) -> 41666.667 | M15: =IF(M$4>=Headcount!$M11,Headcount!$N11,0) -> 41666.667 | ... AO15: =IF(AO$4>=Headcount!$M11,Headcount!$N11,0) -> 41666.667
A16: =Headcount!B12 -> Theoretical Physicist — consulting agreement 2 | B16: =Headcount!D12 -> EnergyWave, Inc. | C16: =IF(Headcount!E12="W-2","Payroll","Consulting") -> Consulting | D16: =IF(Headcount!E12="W-2","Salary & load","Consulting fee") -> Consulting fee | E16: =SUM(F16:AO16) -> 1416666.7 | F16: =IF(F$4>=Headcount!$M12,Headcount!$N12,0) -> 0 | G16: =IF(G$4>=Headcount!$M12,Headcount!$N12,0) -> 0 | H16: =IF(H$4>=Headcount!$M12,Headcount!$N12,0) -> 41666.667 | I16: =IF(I$4>=Headcount!$M12,Headcount!$N12,0) -> 41666.667 | J16: =IF(J$4>=Headcount!$M12,Headcount!$N12,0) -> 41666.667 | K16: =IF(K$4>=Headcount!$M12,Headcount!$N12,0) -> 41666.667 | L16: =IF(L$4>=Headcount!$M12,Headcount!$N12,0) -> 41666.667 | M16: =IF(M$4>=Headcount!$M12,Headcount!$N12,0) -> 41666.667 | ... AO16: =IF(AO$4>=Headcount!$M12,Headcount!$N12,0) -> 41666.667
A17: =Headcount!B13 -> Lab Safety / EHS Officer | B17: =Headcount!D13 -> EnergyWave, Inc. | C17: =IF(Headcount!E13="W-2","Payroll","Consulting") -> Payroll | D17: =IF(Headcount!E13="W-2","Salary & load","Consulting fee") -> Salary & load | E17: =SUM(F17:AO17) -> 439200 | F17: =IF(F$4>=Headcount!$M13,Headcount!$N13,0) -> 12200 | G17: =IF(G$4>=Headcount!$M13,Headcount!$N13,0) -> 12200 | H17: =IF(H$4>=Headcount!$M13,Headcount!$N13,0) -> 12200 | I17: =IF(I$4>=Headcount!$M13,Headcount!$N13,0) -> 12200 | J17: =IF(J$4>=Headcount!$M13,Headcount!$N13,0) -> 12200 | K17: =IF(K$4>=Headcount!$M13,Headcount!$N13,0) -> 12200 | L17: =IF(L$4>=Headcount!$M13,Headcount!$N13,0) -> 12200 | M17: =IF(M$4>=Headcount!$M13,Headcount!$N13,0) -> 12200 | ... AO17: =IF(AO$4>=Headcount!$M13,Headcount!$N13,0) -> 12200
A18: =Headcount!B14 -> Test & Instrumentation Engineer 1 (calorimetry) | B18: =Headcount!D14 -> EnergyWave, Inc. | C18: =IF(Headcount!E14="W-2","Payroll","Consulting") -> Payroll | D18: =IF(Headcount!E14="W-2","Salary & load","Consulting fee") -> Salary & load | E18: =SUM(F18:AO18) -> 480375 | F18: =IF(F$4>=Headcount!$M14,Headcount!$N14,0) -> 0 | G18: =IF(G$4>=Headcount!$M14,Headcount!$N14,0) -> 13725 | H18: =IF(H$4>=Headcount!$M14,Headcount!$N14,0) -> 13725 | I18: =IF(I$4>=Headcount!$M14,Headcount!$N14,0) -> 13725 | J18: =IF(J$4>=Headcount!$M14,Headcount!$N14,0) -> 13725 | K18: =IF(K$4>=Headcount!$M14,Headcount!$N14,0) -> 13725 | L18: =IF(L$4>=Headcount!$M14,Headcount!$N14,0) -> 13725 | M18: =IF(M$4>=Headcount!$M14,Headcount!$N14,0) -> 13725 | ... AO18: =IF(AO$4>=Headcount!$M14,Headcount!$N14,0) -> 13725
A19: =Headcount!B15 -> Test & Instrumentation Engineer 2 | B19: =Headcount!D15 -> EnergyWave, Inc. | C19: =IF(Headcount!E15="W-2","Payroll","Consulting") -> Payroll | D19: =IF(Headcount!E15="W-2","Salary & load","Consulting fee") -> Salary & load | E19: =SUM(F19:AO19) -> 452925 | F19: =IF(F$4>=Headcount!$M15,Headcount!$N15,0) -> 0 | G19: =IF(G$4>=Headcount!$M15,Headcount!$N15,0) -> 0 | H19: =IF(H$4>=Headcount!$M15,Headcount!$N15,0) -> 0 | I19: =IF(I$4>=Headcount!$M15,Headcount!$N15,0) -> 13725 | J19: =IF(J$4>=Headcount!$M15,Headcount!$N15,0) -> 13725 | K19: =IF(K$4>=Headcount!$M15,Headcount!$N15,0) -> 13725 | L19: =IF(L$4>=Headcount!$M15,Headcount!$N15,0) -> 13725 | M19: =IF(M$4>=Headcount!$M15,Headcount!$N15,0) -> 13725 | ... AO19: =IF(AO$4>=Headcount!$M15,Headcount!$N15,0) -> 13725
... A25: =Headcount!B21 -> Government Liaison (consulting) | B25: =Headcount!D21 -> EnergyWave, Inc. | C25: =IF(Headcount!E21="W-2","Payroll","Consulting") -> Consulting | D25: =IF(Headcount!E21="W-2","Salary & load","Consulting fee") -> Consulting fee | E25: =SUM(F25:AO25) -> 180000 | F25: =IF(F$4>=Headcount!$M21,Headcount!$N21,0) -> 5000 | G25: =IF(G$4>=Headcount!$M21,Headcount!$N21,0) -> 5000 | H25: =IF(H$4>=Headcount!$M21,Headcount!$N21,0) -> 5000 | I25: =IF(I$4>=Headcount!$M21,Headcount!$N21,0) -> 5000 | J25: =IF(J$4>=Headcount!$M21,Headcount!$N21,0) -> 5000 | K25: =IF(K$4>=Headcount!$M21,Headcount!$N21,0) -> 5000 | L25: =IF(L$4>=Headcount!$M21,Headcount!$N21,0) -> 5000 | M25: =IF(M$4>=Headcount!$M21,Headcount!$N21,0) -> 5000 | ... AO25: =IF(AO$4>=Headcount!$M21,Headcount!$N21,0) -> 5000
A26: Relocation (one-time, all hires) | B26: EnergyWave, Inc. | C26: Payroll | D26: Relocation | E26: =SUM(F26:AO26) -> 195000 | F26: =SUMPRODUCT((Headcount!$M$4:$M$21=F$4)*Headcount!$H$4:$H$21) -> 10000 | G26: =SUMPRODUCT((Headcount!$M$4:$M$21=G$4)*Headcount!$H$4:$H$21) -> 65000 | H26: =SUMPRODUCT((Headcount!$M$4:$M$21=H$4)*Headcount!$H$4:$H$21) -> 55000 | I26: =SUMPRODUCT((Headcount!$M$4:$M$21=I$4)*Headcount!$H$4:$H$21) -> 40000 | J26: =SUMPRODUCT((Headcount!$M$4:$M$21=J$4)*Headcount!$H$4:$H$21) -> 25000 | K26: =SUMPRODUCT((Headcount!$M$4:$M$21=K$4)*Headcount!$H$4:$H$21) -> 0 | L26: =SUMPRODUCT((Headcount!$M$4:$M$21=L$4)*Headcount!$H$4:$H$21) -> 0 | M26: =SUMPRODUCT((Headcount!$M$4:$M$21=M$4)*Headcount!$H$4:$H$21) -> 0 | ... AO26: =SUMPRODUCT((Headcount!$M$4:$M$21=AO$4)*Headcount!$H$4:$H$21) -> 0
A27: NON-PAYROLL (from CostLines)
A28: =CostLines!B4 -> Office + lab lease near UCI (University Research Park) | B28: =CostLines!C4 -> EnergyWave, Inc. | C28: =CostLines!D4 -> Facilities | D28: =CostLines!E4 -> Lease | E28: =SUM(F28:AO28) -> 787500 | F28: =IF(CostLines!$F4="One-time",IF(F$4=CostLines!$N4,CostLines!$J4,0),IF(AND(F$4>=CostLines!$N4,IF(CostLines!$O4="",TRUE(),F$4<CostLines!$N4+CostLines!$O4)),CostLines!$P4,0)) -> 0 | G28: =IF(CostLines!$F4="One-time",IF(G$4=CostLines!$N4,CostLines!$J4,0),IF(AND(G$4>=CostLines!$N4,IF(CostLines!$O4="",TRUE(),G$4<CostLines!$N4+CostLines!$O4)),CostLines!$P4,0)) -> 22500 | H28: =IF(CostLines!$F4="One-time",IF(H$4=CostLines!$N4,CostLines!$J4,0),IF(AND(H$4>=CostLines!$N4,IF(CostLines!$O4="",TRUE(),H$4<CostLines!$N4+CostLines!$O4)),CostLines!$P4,0)) -> 22500 | I28: =IF(CostLines!$F4="One-time",IF(I$4=CostLines!$N4,CostLines!$J4,0),IF(AND(I$4>=CostLines!$N4,IF(CostLines!$O4="",TRUE(),I$4<CostLines!$N4+CostLines!$O4)),CostLines!$P4,0)) -> 22500 | J28: =IF(CostLines!$F4="One-time",IF(J$4=CostLines!$N4,CostLines!$J4,0),IF(AND(J$4>=CostLines!$N4,IF(CostLines!$O4="",TRUE(),J$4<CostLines!$N4+CostLines!$O4)),CostLines!$P4,0)) -> 22500 | K28: =IF(CostLines!$F4="One-time",IF(K$4=CostLines!$N4,CostLines!$J4,0),IF(AND(K$4>=CostLines!$N4,IF(CostLines!$O4="",TRUE(),K$4<CostLines!$N4+CostLines!$O4)),CostLines!$P4,0)) -> 22500 | L28: =IF(CostLines!$F4="One-time",IF(L$4=CostLines!$N4,CostLines!$J4,0),IF(AND(L$4>=CostLines!$N4,IF(CostLines!$O4="",TRUE(),L$4<CostLines!$N4+CostLines!$O4)),CostLines!$P4,0)) -> 22500 | M28: =IF(CostLines!$F4="One-time",IF(M$4=CostLines!$N4,CostLines!$J4,0),IF(AND(M$4>=CostLines!$N4,IF(CostLines!$O4="",TRUE(),M$4<CostLines!$N4+CostLines!$O4)),CostLines!$P4,0)) -> 22500 | ... AO28: =IF(CostLines!$F4="One-time",IF(AO$4=CostLines!$N4,CostLines!$J4,0),IF(AND(AO$4>=CostLines!$N4,IF(CostLines!$O4="",TRUE(),AO$4<CostLines!$N4+CostLines!$O4)),CostLines!$P4,0)) -> 22500
A29: =CostLines!B5 -> Security deposit | B29: =CostLines!C5 -> EnergyWave, Inc. | C29: =CostLines!D5 -> Facilities | D29: =CostLines!E5 -> Deposit | E29: =SUM(F29:AO29) -> 45000 | F29: =IF(CostLines!$F5="One-time",IF(F$4=CostLines!$N5,CostLines!$J5,0),IF(AND(F$4>=CostLines!$N5,IF(CostLines!$O5="",TRUE(),F$4<CostLines!$N5+CostLines!$O5)),CostLines!$P5,0)) -> 0 | G29: =IF(CostLines!$F5="One-time",IF(G$4=CostLines!$N5,CostLines!$J5,0),IF(AND(G$4>=CostLines!$N5,IF(CostLines!$O5="",TRUE(),G$4<CostLines!$N5+CostLines!$O5)),CostLines!$P5,0)) -> 45000 | H29: =IF(CostLines!$F5="One-time",IF(H$4=CostLines!$N5,CostLines!$J5,0),IF(AND(H$4>=CostLines!$N5,IF(CostLines!$O5="",TRUE(),H$4<CostLines!$N5+CostLines!$O5)),CostLines!$P5,0)) -> 0 | I29: =IF(CostLines!$F5="One-time",IF(I$4=CostLines!$N5,CostLines!$J5,0),IF(AND(I$4>=CostLines!$N5,IF(CostLines!$O5="",TRUE(),I$4<CostLines!$N5+CostLines!$O5)),CostLines!$P5,0)) -> 0 | J29: =IF(CostLines!$F5="One-time",IF(J$4=CostLines!$N5,CostLines!$J5,0),IF(AND(J$4>=CostLines!$N5,IF(CostLines!$O5="",TRUE(),J$4<CostLines!$N5+CostLines!$O5)),CostLines!$P5,0)) -> 0 | K29: =IF(CostLines!$F5="One-time",IF(K$4=CostLines!$N5,CostLines!$J5,0),IF(AND(K$4>=CostLines!$N5,IF(CostLines!$O5="",TRUE(),K$4<CostLines!$N5+CostLines!$O5)),CostLines!$P5,0)) -> 0 | L29: =IF(CostLines!$F5="One-time",IF(L$4=CostLines!$N5,CostLines!$J5,0),IF(AND(L$4>=CostLines!$N5,IF(CostLines!$O5="",TRUE(),L$4<CostLines!$N5+CostLines!$O5)),CostLines!$P5,0)) -> 0 | M29: =IF(CostLines!$F5="One-time",IF(M$4=CostLines!$N5,CostLines!$J5,0),IF(AND(M$4>=CostLines!$N5,IF(CostLines!$O5="",TRUE(),M$4<CostLines!$N5+CostLines!$O5)),CostLines!$P5,0)) -> 0 | ... AO29: =IF(CostLines!$F5="One-time",IF(AO$4=CostLines!$N5,CostLines!$J5,0),IF(AND(AO$4>=CostLines!$N5,IF(CostLines!$O5="",TRUE(),AO$4<CostLines!$N5+CostLines!$O5)),CostLines!$P5,0)) -> 0
A30: =CostLines!B6 -> Lab build-out (power, ventilation, benches, shielding) | B30: =CostLines!C6 -> EnergyWave, Inc. | C30: =CostLines!D6 -> Facilities | D30: =CostLines!E6 -> Build-out | E30: =SUM(F30:AO30) -> 300000 | F30: =IF(CostLines!$F6="One-time",IF(F$4=CostLines!$N6,CostLines!$J6,0),IF(AND(F$4>=CostLines!$N6,IF(CostLines!$O6="",TRUE(),F$4<CostLines!$N6+CostLines!$O6)),CostLines!$P6,0)) -> 0 | G30: =IF(CostLines!$F6="One-time",IF(G$4=CostLines!$N6,CostLines!$J6,0),IF(AND(G$4>=CostLines!$N6,IF(CostLines!$O6="",TRUE(),G$4<CostLines!$N6+CostLines!$O6)),CostLines!$P6,0)) -> 300000 | H30: =IF(CostLines!$F6="One-time",IF(H$4=CostLines!$N6,CostLines!$J6,0),IF(AND(H$4>=CostLines!$N6,IF(CostLines!$O6="",TRUE(),H$4<CostLines!$N6+CostLines!$O6)),CostLines!$P6,0)) -> 0 | I30: =IF(CostLines!$F6="One-time",IF(I$4=CostLines!$N6,CostLines!$J6,0),IF(AND(I$4>=CostLines!$N6,IF(CostLines!$O6="",TRUE(),I$4<CostLines!$N6+CostLines!$O6)),CostLines!$P6,0)) -> 0 | J30: =IF(CostLines!$F6="One-time",IF(J$4=CostLines!$N6,CostLines!$J6,0),IF(AND(J$4>=CostLines!$N6,IF(CostLines!$O6="",TRUE(),J$4<CostLines!$N6+CostLines!$O6)),CostLines!$P6,0)) -> 0 | K30: =IF(CostLines!$F6="One-time",IF(K$4=CostLines!$N6,CostLines!$J6,0),IF(AND(K$4>=CostLines!$N6,IF(CostLines!$O6="",TRUE(),K$4<CostLines!$N6+CostLines!$O6)),CostLines!$P6,0)) -> 0 | L30: =IF(CostLines!$F6="One-time",IF(L$4=CostLines!$N6,CostLines!$J6,0),IF(AND(L$4>=CostLines!$N6,IF(CostLines!$O6="",TRUE(),L$4<CostLines!$N6+CostLines!$O6)),CostLines!$P6,0)) -> 0 | M30: =IF(CostLines!$F6="One-time",IF(M$4=CostLines!$N6,CostLines!$J6,0),IF(AND(M$4>=CostLines!$N6,IF(CostLines!$O6="",TRUE(),M$4<CostLines!$N6+CostLines!$O6)),CostLines!$P6,0)) -> 0 | ... AO30: =IF(CostLines!$F6="One-time",IF(AO$4=CostLines!$N6,CostLines!$J6,0),IF(AND(AO$4>=CostLines!$N6,IF(CostLines!$O6="",TRUE(),AO$4<CostLines!$N6+CostLines!$O6)),CostLines!$P6,0)) -> 0
A31: =CostLines!B7 -> Utilities, internet, security | B31: =CostLines!C7 -> EnergyWave, Inc. | C31: =CostLines!D7 -> Facilities | D31: =CostLines!E7 -> Utilities | E31: =SUM(F31:AO31) -> 140000 | F31: =IF(CostLines!$F7="One-time",IF(F$4=CostLines!$N7,CostLines!$J7,0),IF(AND(F$4>=CostLines!$N7,IF(CostLines!$O7="",TRUE(),F$4<CostLines!$N7+CostLines!$O7)),CostLines!$P7,0)) -> 0 | G31: =IF(CostLines!$F7="One-time",IF(G$4=CostLines!$N7,CostLines!$J7,0),IF(AND(G$4>=CostLines!$N7,IF(CostLines!$O7="",TRUE(),G$4<CostLines!$N7+CostLines!$O7)),CostLines!$P7,0)) -> 4000 | H31: =IF(CostLines!$F7="One-time",IF(H$4=CostLines!$N7,CostLines!$J7,0),IF(AND(H$4>=CostLines!$N7,IF(CostLines!$O7="",TRUE(),H$4<CostLines!$N7+CostLines!$O7)),CostLines!$P7,0)) -> 4000 | I31: =IF(CostLines!$F7="One-time",IF(I$4=CostLines!$N7,CostLines!$J7,0),IF(AND(I$4>=CostLines!$N7,IF(CostLines!$O7="",TRUE(),I$4<CostLines!$N7+CostLines!$O7)),CostLines!$P7,0)) -> 4000 | J31: =IF(CostLines!$F7="One-time",IF(J$4=CostLines!$N7,CostLines!$J7,0),IF(AND(J$4>=CostLines!$N7,IF(CostLines!$O7="",TRUE(),J$4<CostLines!$N7+CostLines!$O7)),CostLines!$P7,0)) -> 4000 | K31: =IF(CostLines!$F7="One-time",IF(K$4=CostLines!$N7,CostLines!$J7,0),IF(AND(K$4>=CostLines!$N7,IF(CostLines!$O7="",TRUE(),K$4<CostLines!$N7+CostLines!$O7)),CostLines!$P7,0)) -> 4000 | L31: =IF(CostLines!$F7="One-time",IF(L$4=CostLines!$N7,CostLines!$J7,0),IF(AND(L$4>=CostLines!$N7,IF(CostLines!$O7="",TRUE(),L$4<CostLines!$N7+CostLines!$O7)),CostLines!$P7,0)) -> 4000 | M31: =IF(CostLines!$F7="One-time",IF(M$4=CostLines!$N7,CostLines!$J7,0),IF(AND(M$4>=CostLines!$N7,IF(CostLines!$O7="",TRUE(),M$4<CostLines!$N7+CostLines!$O7)),CostLines!$P7,0)) -> 4000 | ... AO31: =IF(CostLines!$F7="One-time",IF(AO$4=CostLines!$N7,CostLines!$J7,0),IF(AND(AO$4>=CostLines!$N7,IF(CostLines!$O7="",TRUE(),AO$4<CostLines!$N7+CostLines!$O7)),CostLines!$P7,0)) -> 4000
A32: =CostLines!B8 -> Tabletop instrumentation package (calorimeters, power analyzers, precision sources/loads, DAQ, thermal chambers, balances, shielded enclosure, reference standards) | B32: =CostLines!C8 -> EnergyWave, Inc. | C32: =CostLines!D8 -> Equipment | D32: =CostLines!E8 -> Instrumentation | E32: =SUM(F32:AO32) -> 450000 | F32: =IF(CostLines!$F8="One-time",IF(F$4=CostLines!$N8,CostLines!$J8,0),IF(AND(F$4>=CostLines!$N8,IF(CostLines!$O8="",TRUE(),F$4<CostLines!$N8+CostLines!$O8)),CostLines!$P8,0)) -> 0 | G32: =IF(CostLines!$F8="One-time",IF(G$4=CostLines!$N8,CostLines!$J8,0),IF(AND(G$4>=CostLines!$N8,IF(CostLines!$O8="",TRUE(),G$4<CostLines!$N8+CostLines!$O8)),CostLines!$P8,0)) -> 450000 | H32: =IF(CostLines!$F8="One-time",IF(H$4=CostLines!$N8,CostLines!$J8,0),IF(AND(H$4>=CostLines!$N8,IF(CostLines!$O8="",TRUE(),H$4<CostLines!$N8+CostLines!$O8)),CostLines!$P8,0)) -> 0 | I32: =IF(CostLines!$F8="One-time",IF(I$4=CostLines!$N8,CostLines!$J8,0),IF(AND(I$4>=CostLines!$N8,IF(CostLines!$O8="",TRUE(),I$4<CostLines!$N8+CostLines!$O8)),CostLines!$P8,0)) -> 0 | J32: =IF(CostLines!$F8="One-time",IF(J$4=CostLines!$N8,CostLines!$J8,0),IF(AND(J$4>=CostLines!$N8,IF(CostLines!$O8="",TRUE(),J$4<CostLines!$N8+CostLines!$O8)),CostLines!$P8,0)) -> 0 | K32: =IF(CostLines!$F8="One-time",IF(K$4=CostLines!$N8,CostLines!$J8,0),IF(AND(K$4>=CostLines!$N8,IF(CostLines!$O8="",TRUE(),K$4<CostLines!$N8+CostLines!$O8)),CostLines!$P8,0)) -> 0 | L32: =IF(CostLines!$F8="One-time",IF(L$4=CostLines!$N8,CostLines!$J8,0),IF(AND(L$4>=CostLines!$N8,IF(CostLines!$O8="",TRUE(),L$4<CostLines!$N8+CostLines!$O8)),CostLines!$P8,0)) -> 0 | M32: =IF(CostLines!$F8="One-time",IF(M$4=CostLines!$N8,CostLines!$J8,0),IF(AND(M$4>=CostLines!$N8,IF(CostLines!$O8="",TRUE(),M$4<CostLines!$N8+CostLines!$O8)),CostLines!$P8,0)) -> 0 | ... AO32: =IF(CostLines!$F8="One-time",IF(AO$4=CostLines!$N8,CostLines!$J8,0),IF(AND(AO$4>=CostLines!$N8,IF(CostLines!$O8="",TRUE(),AO$4<CostLines!$N8+CostLines!$O8)),CostLines!$P8,0)) -> 0
A33: =CostLines!B9 -> Calibration & metrology services | B33: =CostLines!C9 -> EnergyWave, Inc. | C33: =CostLines!D9 -> Equipment | D33: =CostLines!E9 -> Calibration | E33: =SUM(F33:AO33) -> 85000 | F33: =IF(CostLines!$F9="One-time",IF(F$4=CostLines!$N9,CostLines!$J9,0),IF(AND(F$4>=CostLines!$N9,IF(CostLines!$O9="",TRUE(),F$4<CostLines!$N9+CostLines!$O9)),CostLines!$P9,0)) -> 0 | G33: =IF(CostLines!$F9="One-time",IF(G$4=CostLines!$N9,CostLines!$J9,0),IF(AND(G$4>=CostLines!$N9,IF(CostLines!$O9="",TRUE(),G$4<CostLines!$N9+CostLines!$O9)),CostLines!$P9,0)) -> 0 | H33: =IF(CostLines!$F9="One-time",IF(H$4=CostLines!$N9,CostLines!$J9,0),IF(AND(H$4>=CostLines!$N9,IF(CostLines!$O9="",TRUE(),H$4<CostLines!$N9+CostLines!$O9)),CostLines!$P9,0)) -> 2500 | I33: =IF(CostLines!$F9="One-time",IF(I$4=CostLines!$N9,CostLines!$J9,0),IF(AND(I$4>=CostLines!$N9,IF(CostLines!$O9="",TRUE(),I$4<CostLines!$N9+CostLines!$O9)),CostLines!$P9,0)) -> 2500 | J33: =IF(CostLines!$F9="One-time",IF(J$4=CostLines!$N9,CostLines!$J9,0),IF(AND(J$4>=CostLines!$N9,IF(CostLines!$O9="",TRUE(),J$4<CostLines!$N9+CostLines!$O9)),CostLines!$P9,0)) -> 2500 | K33: =IF(CostLines!$F9="One-time",IF(K$4=CostLines!$N9,CostLines!$J9,0),IF(AND(K$4>=CostLines!$N9,IF(CostLines!$O9="",TRUE(),K$4<CostLines!$N9+CostLines!$O9)),CostLines!$P9,0)) -> 2500 | L33: =IF(CostLines!$F9="One-time",IF(L$4=CostLines!$N9,CostLines!$J9,0),IF(AND(L$4>=CostLines!$N9,IF(CostLines!$O9="",TRUE(),L$4<CostLines!$N9+CostLines!$O9)),CostLines!$P9,0)) -> 2500 | M33: =IF(CostLines!$F9="One-time",IF(M$4=CostLines!$N9,CostLines!$J9,0),IF(AND(M$4>=CostLines!$N9,IF(CostLines!$O9="",TRUE(),M$4<CostLines!$N9+CostLines!$O9)),CostLines!$P9,0)) -> 2500 | ... AO33: =IF(CostLines!$F9="One-time",IF(AO$4=CostLines!$N9,CostLines!$J9,0),IF(AND(AO$4>=CostLines!$N9,IF(CostLines!$O9="",TRUE(),AO$4<CostLines!$N9+CostLines!$O9)),CostLines!$P9,0)) -> 2500
A34: =CostLines!B10 -> Precision additive-manufacturing system (high-resolution AM with closed-loop process control) | B34: =CostLines!C10 -> EnergyWave, Inc. | C34: =CostLines!D10 -> Equipment | D34: =CostLines!E10 -> Additive manufacturing | E34: =SUM(F34:AO34) -> 750000 | F34: =IF(CostLines!$F10="One-time",IF(F$4=CostLines!$N10,CostLines!$J10,0),IF(AND(F$4>=CostLines!$N10,IF(CostLines!$O10="",TRUE(),F$4<CostLines!$N10+CostLines!$O10)),CostLines!$P10,0)) -> 0 | G34: =IF(CostLines!$F10="One-time",IF(G$4=CostLines!$N10,CostLines!$J10,0),IF(AND(G$4>=CostLines!$N10,IF(CostLines!$O10="",TRUE(),G$4<CostLines!$N10+CostLines!$O10)),CostLines!$P10,0)) -> 0 | H34: =IF(CostLines!$F10="One-time",IF(H$4=CostLines!$N10,CostLines!$J10,0),IF(AND(H$4>=CostLines!$N10,IF(CostLines!$O10="",TRUE(),H$4<CostLines!$N10+CostLines!$O10)),CostLines!$P10,0)) -> 750000 | I34: =IF(CostLines!$F10="One-time",IF(I$4=CostLines!$N10,CostLines!$J10,0),IF(AND(I$4>=CostLines!$N10,IF(CostLines!$O10="",TRUE(),I$4<CostLines!$N10+CostLines!$O10)),CostLines!$P10,0)) -> 0 | J34: =IF(CostLines!$F10="One-time",IF(J$4=CostLines!$N10,CostLines!$J10,0),IF(AND(J$4>=CostLines!$N10,IF(CostLines!$O10="",TRUE(),J$4<CostLines!$N10+CostLines!$O10)),CostLines!$P10,0)) -> 0 | K34: =IF(CostLines!$F10="One-time",IF(K$4=CostLines!$N10,CostLines!$J10,0),IF(AND(K$4>=CostLines!$N10,IF(CostLines!$O10="",TRUE(),K$4<CostLines!$N10+CostLines!$O10)),CostLines!$P10,0)) -> 0 | L34: =IF(CostLines!$F10="One-time",IF(L$4=CostLines!$N10,CostLines!$J10,0),IF(AND(L$4>=CostLines!$N10,IF(CostLines!$O10="",TRUE(),L$4<CostLines!$N10+CostLines!$O10)),CostLines!$P10,0)) -> 0 | M34: =IF(CostLines!$F10="One-time",IF(M$4=CostLines!$N10,CostLines!$J10,0),IF(AND(M$4>=CostLines!$N10,IF(CostLines!$O10="",TRUE(),M$4<CostLines!$N10+CostLines!$O10)),CostLines!$P10,0)) -> 0 | ... AO34: =IF(CostLines!$F10="One-time",IF(AO$4=CostLines!$N10,CostLines!$J10,0),IF(AND(AO$4>=CostLines!$N10,IF(CostLines!$O10="",TRUE(),AO$4<CostLines!$N10+CostLines!$O10)),CostLines!$P10,0)) -> 0
A35: =CostLines!B11 -> AM service contract & software | B35: =CostLines!C11 -> EnergyWave, Inc. | C35: =CostLines!D11 -> Equipment | D35: =CostLines!E11 -> Additive manufacturing | E35: =SUM(F35:AO35) -> 110000 | F35: =IF(CostLines!$F11="One-time",IF(F$4=CostLines!$N11,CostLines!$J11,0),IF(AND(F$4>=CostLines!$N11,IF(CostLines!$O11="",TRUE(),F$4<CostLines!$N11+CostLines!$O11)),CostLines!$P11,0)) -> 0 | G35: =IF(CostLines!$F11="One-time",IF(G$4=CostLines!$N11,CostLines!$J11,0),IF(AND(G$4>=CostLines!$N11,IF(CostLines!$O11="",TRUE(),G$4<CostLines!$N11+CostLines!$O11)),CostLines!$P11,0)) -> 0 | H35: =IF(CostLines!$F11="One-time",IF(H$4=CostLines!$N11,CostLines!$J11,0),IF(AND(H$4>=CostLines!$N11,IF(CostLines!$O11="",TRUE(),H$4<CostLines!$N11+CostLines!$O11)),CostLines!$P11,0)) -> 0 | I35: =IF(CostLines!$F11="One-time",IF(I$4=CostLines!$N11,CostLines!$J11,0),IF(AND(I$4>=CostLines!$N11,IF(CostLines!$O11="",TRUE(),I$4<CostLines!$N11+CostLines!$O11)),CostLines!$P11,0)) -> 3333.3333 | J35: =IF(CostLines!$F11="One-time",IF(J$4=CostLines!$N11,CostLines!$J11,0),IF(AND(J$4>=CostLines!$N11,IF(CostLines!$O11="",TRUE(),J$4<CostLines!$N11+CostLines!$O11)),CostLines!$P11,0)) -> 3333.3333 | K35: =IF(CostLines!$F11="One-time",IF(K$4=CostLines!$N11,CostLines!$J11,0),IF(AND(K$4>=CostLines!$N11,IF(CostLines!$O11="",TRUE(),K$4<CostLines!$N11+CostLines!$O11)),CostLines!$P11,0)) -> 3333.3333 | L35: =IF(CostLines!$F11="One-time",IF(L$4=CostLines!$N11,CostLines!$J11,0),IF(AND(L$4>=CostLines!$N11,IF(CostLines!$O11="",TRUE(),L$4<CostLines!$N11+CostLines!$O11)),CostLines!$P11,0)) -> 3333.3333 | M35: =IF(CostLines!$F11="One-time",IF(M$4=CostLines!$N11,CostLines!$J11,0),IF(AND(M$4>=CostLines!$N11,IF(CostLines!$O11="",TRUE(),M$4<CostLines!$N11+CostLines!$O11)),CostLines!$P11,0)) -> 3333.3333 | ... AO35: =IF(CostLines!$F11="One-time",IF(AO$4=CostLines!$N11,CostLines!$J11,0),IF(AND(AO$4>=CostLines!$N11,IF(CostLines!$O11="",TRUE(),AO$4<CostLines!$N11+CostLines!$O11)),CostLines!$P11,0)) -> 3333.3333
A36: =CostLines!B12 -> AM feedstock & lab consumables | B36: =CostLines!C12 -> EnergyWave, Inc. | C36: =CostLines!D12 -> Operations | D36: =CostLines!E12 -> Consumables | E36: =SUM(F36:AO36) -> 340000 | F36: =IF(CostLines!$F12="One-time",IF(F$4=CostLines!$N12,CostLines!$J12,0),IF(AND(F$4>=CostLines!$N12,IF(CostLines!$O12="",TRUE(),F$4<CostLines!$N12+CostLines!$O12)),CostLines!$P12,0)) -> 0 | G36: =IF(CostLines!$F12="One-time",IF(G$4=CostLines!$N12,CostLines!$J12,0),IF(AND(G$4>=CostLines!$N12,IF(CostLines!$O12="",TRUE(),G$4<CostLines!$N12+CostLines!$O12)),CostLines!$P12,0)) -> 0 | H36: =IF(CostLines!$F12="One-time",IF(H$4=CostLines!$N12,CostLines!$J12,0),IF(AND(H$4>=CostLines!$N12,IF(CostLines!$O12="",TRUE(),H$4<CostLines!$N12+CostLines!$O12)),CostLines!$P12,0)) -> 10000 | I36: =IF(CostLines!$F12="One-time",IF(I$4=CostLines!$N12,CostLines!$J12,0),IF(AND(I$4>=CostLines!$N12,IF(CostLines!$O12="",TRUE(),I$4<CostLines!$N12+CostLines!$O12)),CostLines!$P12,0)) -> 10000 | J36: =IF(CostLines!$F12="One-time",IF(J$4=CostLines!$N12,CostLines!$J12,0),IF(AND(J$4>=CostLines!$N12,IF(CostLines!$O12="",TRUE(),J$4<CostLines!$N12+CostLines!$O12)),CostLines!$P12,0)) -> 10000 | K36: =IF(CostLines!$F12="One-time",IF(K$4=CostLines!$N12,CostLines!$J12,0),IF(AND(K$4>=CostLines!$N12,IF(CostLines!$O12="",TRUE(),K$4<CostLines!$N12+CostLines!$O12)),CostLines!$P12,0)) -> 10000 | L36: =IF(CostLines!$F12="One-time",IF(L$4=CostLines!$N12,CostLines!$J12,0),IF(AND(L$4>=CostLines!$N12,IF(CostLines!$O12="",TRUE(),L$4<CostLines!$N12+CostLines!$O12)),CostLines!$P12,0)) -> 10000 | M36: =IF(CostLines!$F12="One-time",IF(M$4=CostLines!$N12,CostLines!$J12,0),IF(AND(M$4>=CostLines!$N12,IF(CostLines!$O12="",TRUE(),M$4<CostLines!$N12+CostLines!$O12)),CostLines!$P12,0)) -> 10000 | ... AO36: =IF(CostLines!$F12="One-time",IF(AO$4=CostLines!$N12,CostLines!$J12,0),IF(AND(AO$4>=CostLines!$N12,IF(CostLines!$O12="",TRUE(),AO$4<CostLines!$N12+CostLines!$O12)),CostLines!$P12,0)) -> 10000
A37: =CostLines!B13 -> Compute, simulation & software licenses | B37: =CostLines!C13 -> EnergyWave, Inc. | C37: =CostLines!D13 -> Operations | D37: =CostLines!E13 -> Compute | E37: =SUM(F37:AO37) -> 288000 | F37: =IF(CostLines!$F13="One-time",IF(F$4=CostLines!$N13,CostLines!$J13,0),IF(AND(F$4>=CostLines!$N13,IF(CostLines!$O13="",TRUE(),F$4<CostLines!$N13+CostLines!$O13)),CostLines!$P13,0)) -> 8000 | G37: =IF(CostLines!$F13="One-time",IF(G$4=CostLines!$N13,CostLines!$J13,0),IF(AND(G$4>=CostLines!$N13,IF(CostLines!$O13="",TRUE(),G$4<CostLines!$N13+CostLines!$O13)),CostLines!$P13,0)) -> 8000 | H37: =IF(CostLines!$F13="One-time",IF(H$4=CostLines!$N13,CostLines!$J13,0),IF(AND(H$4>=CostLines!$N13,IF(CostLines!$O13="",TRUE(),H$4<CostLines!$N13+CostLines!$O13)),CostLines!$P13,0)) -> 8000 | I37: =IF(CostLines!$F13="One-time",IF(I$4=CostLines!$N13,CostLines!$J13,0),IF(AND(I$4>=CostLines!$N13,IF(CostLines!$O13="",TRUE(),I$4<CostLines!$N13+CostLines!$O13)),CostLines!$P13,0)) -> 8000 | J37: =IF(CostLines!$F13="One-time",IF(J$4=CostLines!$N13,CostLines!$J13,0),IF(AND(J$4>=CostLines!$N13,IF(CostLines!$O13="",TRUE(),J$4<CostLines!$N13+CostLines!$O13)),CostLines!$P13,0)) -> 8000 | K37: =IF(CostLines!$F13="One-time",IF(K$4=CostLines!$N13,CostLines!$J13,0),IF(AND(K$4>=CostLines!$N13,IF(CostLines!$O13="",TRUE(),K$4<CostLines!$N13+CostLines!$O13)),CostLines!$P13,0)) -> 8000 | L37: =IF(CostLines!$F13="One-time",IF(L$4=CostLines!$N13,CostLines!$J13,0),IF(AND(L$4>=CostLines!$N13,IF(CostLines!$O13="",TRUE(),L$4<CostLines!$N13+CostLines!$O13)),CostLines!$P13,0)) -> 8000 | M37: =IF(CostLines!$F13="One-time",IF(M$4=CostLines!$N13,CostLines!$J13,0),IF(AND(M$4>=CostLines!$N13,IF(CostLines!$O13="",TRUE(),M$4<CostLines!$N13+CostLines!$O13)),CostLines!$P13,0)) -> 8000 | ... AO37: =IF(CostLines!$F13="One-time",IF(AO$4=CostLines!$N13,CostLines!$J13,0),IF(AND(AO$4>=CostLines!$N13,IF(CostLines!$O13="",TRUE(),AO$4<CostLines!$N13+CostLines!$O13)),CostLines!$P13,0)) -> 8000
